Traceback (most recent call last):
  File "C:\Users\u.shermetov\AppData\Roaming\Python\Python310\site-packages\aiohttp\connector.py", line 1115, in _wrap_create_connection
    sock = await aiohappyeyeballs.start_connection(
  File "C:\Users\u.shermetov\AppData\Roaming\Python\Python310\site-packages\aiohappyeyeballs\impl.py", line 122, in start_connection
    raise first_exception
  File "C:\Users\u.shermetov\AppData\Roaming\Python\Python310\site-packages\aiohappyeyeballs\impl.py", line 73, in start_connection
    sock = await _connect_sock(
  File "C:\Users\u.shermetov\AppData\Roaming\Python\Python310\site-packages\aiohappyeyeballs\impl.py", line 208, in _connect_sock
    await loop.sock_connect(sock, address)
  File "C:\Program Files\Python310\lib\asyncio\proactor_events.py", line 709, in sock_connect
    return await self._proactor.connect(sock, address)
  File "C:\Program Files\Python310\lib\asyncio\windows_events.py", line 826, in _poll
    value = callback(transferred, key, ov)
  File "C:\Program Files\Python310\lib\asyncio\windows_events.py", line 613, in finish_connect
    ov.getresult()
OSError: [WinError 121] Превышен таймаут семафора

The above exception was the direct cause of the following exception:

Traceback (most recent call last):
  File "C:\Users\u.shermetov\AppData\Roaming\Python\Python310\site-packages\aiogram\client\session\aiohttp.py", line 177, in make_request
    async with session.post(
  File "C:\Users\u.shermetov\AppData\Roaming\Python\Python310\site-packages\aiohttp\client.py", line 1425, in __aenter__
    self._resp: _RetType = await self._coro
  File "C:\Users\u.shermetov\AppData\Roaming\Python\Python310\site-packages\aiohttp\client.py", line 703, in _request
    conn = await self._connector.connect(
  File "C:\Users\u.shermetov\AppData\Roaming\Python\Python310\site-packages\aiohttp\connector.py", line 548, in connect
    proto = await self._create_connection(req, traces, timeout)
  File "C:\Users\u.shermetov\AppData\Roaming\Python\Python310\site-packages\aiohttp\connector.py", line 1056, in _create_connection
    _, proto = await self._create_direct_connection(req, traces, timeout)
  File "C:\Users\u.shermetov\AppData\Roaming\Python\Python310\site-packages\aiohttp\connector.py", line 1400, in _create_direct_connection
    raise last_exc
  File "C:\Users\u.shermetov\AppData\Roaming\Python\Python310\site-packages\aiohttp\connector.py", line 1369, in _create_direct_connection
    transp, proto = await self._wrap_create_connection(
  File "C:\Users\u.shermetov\AppData\Roaming\Python\Python310\site-packages\aiohttp\connector.py", line 1130, in _wrap_create_connection
    raise client_error(req.connection_key, exc) from exc
aiohttp.client_exceptions.ClientConnectorError: Cannot connect to host api.telegram.org:443 ssl:default [Превышен таймаут семафора]

During handling of the above exception, another exception occurred:

Traceback (most recent call last):
  File "D:\Any\F\clc\tg\main.py", line 45, in <module>
    asyncio.run(main())
  File "C:\Program Files\Python310\lib\asyncio\runners.py", line 44, in run
    return loop.run_until_complete(main)
  File "C:\Program Files\Python310\lib\asyncio\base_events.py", line 649, in run_until_complete
    return future.result()
  File "D:\Any\F\clc\tg\main.py", line 35, in main
    await set_commands(bot)
  File "D:\Any\F\clc\tg\main.py", line 26, in set_commands
    await bot.set_my_commands(bot_commands)
  File "C:\Users\u.shermetov\AppData\Roaming\Python\Python310\site-packages\aiogram\client\bot.py", line 3591, in set_my_commands
    return await self(call, request_timeout=request_timeout)
  File "C:\Users\u.shermetov\AppData\Roaming\Python\Python310\site-packages\aiogram\client\bot.py", line 478, in __call__
    return await self.session(self, method, timeout=request_timeout)
  File "C:\Users\u.shermetov\AppData\Roaming\Python\Python310\site-packages\aiogram\client\session\base.py", line 254, in __call__
    return cast(TelegramType, await middleware(bot, method))
  File "C:\Users\u.shermetov\AppData\Roaming\Python\Python310\site-packages\aiogram\client\session\aiohttp.py", line 184, in make_request
    raise TelegramNetworkError(method=method, message=f"{type(e).__name__}: {e}")
aiogram.exceptions.TelegramNetworkError: HTTP Client says - ClientConnectorError: Cannot connect to host api.telegram.org:443 ssl:default [Превышен таймаут семафора]      
